
2025-10-30 00:35:13,825 [INFO] django.utils.autoreload: Watching for file changes with StatReloader
2025-10-30 00:51:19,354 [INFO] django.utils.autoreload: C:\Users\DELL\Desktop\Posts\myproject\myproject\settings.py changed, reloading.
2025-10-30 00:51:20,940 [INFO] django.utils.autoreload: Watching for file changes with StatReloader
2025-10-30 00:51:45,816 [INFO] myapp.views: start order to register
2025-10-30 00:51:45,821 [ERROR] myapp.views: this email is already exist
2025-10-30 00:51:45,823 [ERROR] myapp.views: something happend this email is already exist
2025-10-30 00:51:45,913 [ERROR] django.request: Internal Server Error: /api/hello/
Traceback (most recent call last):
  File "C:\Users\DELL\Desktop\Posts\myproject\myapp\views.py", line 56, in register
    raise ValueError("this email is already exist")
ValueError: this email is already exist

During handling of the above exception, another exception occurred:

Traceback (most recent call last):
  File "C:\Users\DELL\Desktop\Posts\venv\Lib\site-packages\rest_framework\views.py", line 512, in dispatch
    response = handler(request, *args, **kwargs)
               ^^^^^^^^^^^^^^^^^^^^^^^^^^^^^^^^^
  File "C:\Users\DELL\Desktop\Posts\venv\Lib\site-packages\rest_framework\decorators.py", line 50, in handler
    return func(*args, **kwargs)
           ^^^^^^^^^^^^^^^^^^^^^
  File "C:\Users\DELL\Desktop\Posts\myproject\myapp\views.py", line 67, in register
    raise ValueError(f"Error : {e}")
ValueError: Error : this email is already exist

During handling of the above exception, another exception occurred:

Traceback (most recent call last):
  File "C:\Users\DELL\Desktop\Posts\venv\Lib\site-packages\rest_framework\settings.py", line 179, in import_from_string
    return import_string(val)
           ^^^^^^^^^^^^^^^^^^
  File "C:\Users\DELL\Desktop\Posts\venv\Lib\site-packages\django\utils\module_loading.py", line 30, in import_string
    return cached_import(module_path, class_name)
           ^^^^^^^^^^^^^^^^^^^^^^^^^^^^^^^^^^^^^^
  File "C:\Users\DELL\Desktop\Posts\venv\Lib\site-packages\django\utils\module_loading.py", line 15, in cached_import
    module = import_module(module_path)
             ^^^^^^^^^^^^^^^^^^^^^^^^^^
  File "C:\Users\DELL\AppData\Local\Programs\Python\Python312\Lib\importlib\__init__.py", line 90, in import_module
    return _bootstrap._gcd_import(name[level:], package, level)
           ^^^^^^^^^^^^^^^^^^^^^^^^^^^^^^^^^^^^^^^^^^^^^^^^^^^^
  File "<frozen importlib._bootstrap>", line 1381, in _gcd_import
  File "<frozen importlib._bootstrap>", line 1354, in _find_and_load
  File "<frozen importlib._bootstrap>", line 1318, in _find_and_load_unlocked
ModuleNotFoundError: No module named 'myproject.utils'

During handling of the above exception, another exception occurred:

Traceback (most recent call last):
  File "C:\Users\DELL\Desktop\Posts\venv\Lib\site-packages\django\core\handlers\exception.py", line 55, in inner
    response = get_response(request)
               ^^^^^^^^^^^^^^^^^^^^^
  File "C:\Users\DELL\Desktop\Posts\venv\Lib\site-packages\django\core\handlers\base.py", line 197, in _get_response
    response = wrapped_callback(request, *callback_args, **callback_kwargs)
               ^^^^^^^^^^^^^^^^^^^^^^^^^^^^^^^^^^^^^^^^^^^^^^^^^^^^^^^^^^^^
  File "C:\Users\DELL\Desktop\Posts\venv\Lib\site-packages\django\views\decorators\csrf.py", line 65, in _view_wrapper
    return view_func(request, *args, **kwargs)
           ^^^^^^^^^^^^^^^^^^^^^^^^^^^^^^^^^^^
  File "C:\Users\DELL\Desktop\Posts\venv\Lib\site-packages\django\views\generic\base.py", line 105, in view
    return self.dispatch(request, *args, **kwargs)
           ^^^^^^^^^^^^^^^^^^^^^^^^^^^^^^^^^^^^^^^
  File "C:\Users\DELL\Desktop\Posts\venv\Lib\site-packages\rest_framework\views.py", line 515, in dispatch
    response = self.handle_exception(exc)
               ^^^^^^^^^^^^^^^^^^^^^^^^^^
  File "C:\Users\DELL\Desktop\Posts\venv\Lib\site-packages\rest_framework\views.py", line 469, in handle_exception
    exception_handler = self.get_exception_handler()
                        ^^^^^^^^^^^^^^^^^^^^^^^^^^^^
  File "C:\Users\DELL\Desktop\Posts\venv\Lib\site-packages\rest_framework\views.py", line 304, in get_exception_handler
    return self.settings.EXCEPTION_HANDLER
           ^^^^^^^^^^^^^^^^^^^^^^^^^^^^^^^
  File "C:\Users\DELL\Desktop\Posts\venv\Lib\site-packages\rest_framework\settings.py", line 227, in __getattr__
    val = perform_import(val, attr)
          ^^^^^^^^^^^^^^^^^^^^^^^^^
  File "C:\Users\DELL\Desktop\Posts\venv\Lib\site-packages\rest_framework\settings.py", line 168, in perform_import
    return import_from_string(val, setting_name)
           ^^^^^^^^^^^^^^^^^^^^^^^^^^^^^^^^^^^^^
  File "C:\Users\DELL\Desktop\Posts\venv\Lib\site-packages\rest_framework\settings.py", line 182, in import_from_string
    raise ImportError(msg)
ImportError: Could not import 'myproject.utils.custom_exception_handler' for API setting 'EXCEPTION_HANDLER'. ModuleNotFoundError: No module named 'myproject.utils'.
2025-10-30 00:53:42,346 [INFO] django.utils.autoreload: C:\Users\DELL\Desktop\Posts\myproject\myproject\settings.py changed, reloading.
2025-10-30 00:53:43,686 [INFO] django.utils.autoreload: Watching for file changes with StatReloader
2025-10-30 00:53:46,671 [INFO] myapp.views: start order to register
2025-10-30 00:53:46,682 [ERROR] myapp.views: this email is already exist
2025-10-30 00:53:46,685 [ERROR] myapp.views: something happend this email is already exist
2025-10-30 00:53:46,789 [ERROR] django.request: Internal Server Error: /api/hello/
Traceback (most recent call last):
  File "C:\Users\DELL\Desktop\Posts\myproject\myapp\views.py", line 56, in register
    raise ValueError("this email is already exist")
ValueError: this email is already exist

During handling of the above exception, another exception occurred:

Traceback (most recent call last):
  File "C:\Users\DELL\Desktop\Posts\venv\Lib\site-packages\rest_framework\views.py", line 512, in dispatch
    response = handler(request, *args, **kwargs)
               ^^^^^^^^^^^^^^^^^^^^^^^^^^^^^^^^^
  File "C:\Users\DELL\Desktop\Posts\venv\Lib\site-packages\rest_framework\decorators.py", line 50, in handler
    return func(*args, **kwargs)
           ^^^^^^^^^^^^^^^^^^^^^
  File "C:\Users\DELL\Desktop\Posts\myproject\myapp\views.py", line 67, in register
    raise ValueError(f"Error : {e}")
ValueError: Error : this email is already exist

During handling of the above exception, another exception occurred:

Traceback (most recent call last):
  File "C:\Users\DELL\Desktop\Posts\venv\Lib\site-packages\rest_framework\settings.py", line 179, in import_from_string
    return import_string(val)
           ^^^^^^^^^^^^^^^^^^
  File "C:\Users\DELL\Desktop\Posts\venv\Lib\site-packages\django\utils\module_loading.py", line 30, in import_string
    return cached_import(module_path, class_name)
           ^^^^^^^^^^^^^^^^^^^^^^^^^^^^^^^^^^^^^^
  File "C:\Users\DELL\Desktop\Posts\venv\Lib\site-packages\django\utils\module_loading.py", line 15, in cached_import
    module = import_module(module_path)
             ^^^^^^^^^^^^^^^^^^^^^^^^^^
  File "C:\Users\DELL\AppData\Local\Programs\Python\Python312\Lib\importlib\__init__.py", line 90, in import_module
    return _bootstrap._gcd_import(name[level:], package, level)
           ^^^^^^^^^^^^^^^^^^^^^^^^^^^^^^^^^^^^^^^^^^^^^^^^^^^^
  File "<frozen importlib._bootstrap>", line 1381, in _gcd_import
  File "<frozen importlib._bootstrap>", line 1354, in _find_and_load
  File "<frozen importlib._bootstrap>", line 1304, in _find_and_load_unlocked
  File "<frozen importlib._bootstrap>", line 488, in _call_with_frames_removed
  File "<frozen importlib._bootstrap>", line 1381, in _gcd_import
  File "<frozen importlib._bootstrap>", line 1354, in _find_and_load
  File "<frozen importlib._bootstrap>", line 1318, in _find_and_load_unlocked
ModuleNotFoundError: No module named 'myproject.myapp'

During handling of the above exception, another exception occurred:

Traceback (most recent call last):
  File "C:\Users\DELL\Desktop\Posts\venv\Lib\site-packages\django\core\handlers\exception.py", line 55, in inner
    response = get_response(request)
               ^^^^^^^^^^^^^^^^^^^^^
  File "C:\Users\DELL\Desktop\Posts\venv\Lib\site-packages\django\core\handlers\base.py", line 197, in _get_response
    response = wrapped_callback(request, *callback_args, **callback_kwargs)
               ^^^^^^^^^^^^^^^^^^^^^^^^^^^^^^^^^^^^^^^^^^^^^^^^^^^^^^^^^^^^
  File "C:\Users\DELL\Desktop\Posts\venv\Lib\site-packages\django\views\decorators\csrf.py", line 65, in _view_wrapper
    return view_func(request, *args, **kwargs)
           ^^^^^^^^^^^^^^^^^^^^^^^^^^^^^^^^^^^
  File "C:\Users\DELL\Desktop\Posts\venv\Lib\site-packages\django\views\generic\base.py", line 105, in view
    return self.dispatch(request, *args, **kwargs)
           ^^^^^^^^^^^^^^^^^^^^^^^^^^^^^^^^^^^^^^^
  File "C:\Users\DELL\Desktop\Posts\venv\Lib\site-packages\rest_framework\views.py", line 515, in dispatch
    response = self.handle_exception(exc)
               ^^^^^^^^^^^^^^^^^^^^^^^^^^
  File "C:\Users\DELL\Desktop\Posts\venv\Lib\site-packages\rest_framework\views.py", line 469, in handle_exception
    exception_handler = self.get_exception_handler()
                        ^^^^^^^^^^^^^^^^^^^^^^^^^^^^
  File "C:\Users\DELL\Desktop\Posts\venv\Lib\site-packages\rest_framework\views.py", line 304, in get_exception_handler
    return self.settings.EXCEPTION_HANDLER
           ^^^^^^^^^^^^^^^^^^^^^^^^^^^^^^^
  File "C:\Users\DELL\Desktop\Posts\venv\Lib\site-packages\rest_framework\settings.py", line 227, in __getattr__
    val = perform_import(val, attr)
          ^^^^^^^^^^^^^^^^^^^^^^^^^
  File "C:\Users\DELL\Desktop\Posts\venv\Lib\site-packages\rest_framework\settings.py", line 168, in perform_import
    return import_from_string(val, setting_name)
           ^^^^^^^^^^^^^^^^^^^^^^^^^^^^^^^^^^^^^
  File "C:\Users\DELL\Desktop\Posts\venv\Lib\site-packages\rest_framework\settings.py", line 182, in import_from_string
    raise ImportError(msg)
ImportError: Could not import 'myproject.myapp.exceptions.custom_exception_handler' for API setting 'EXCEPTION_HANDLER'. ModuleNotFoundError: No module named 'myproject.myapp'.
2025-10-30 00:55:02,316 [INFO] django.utils.autoreload: C:\Users\DELL\Desktop\Posts\myproject\myproject\settings.py changed, reloading.
2025-10-30 00:55:03,750 [INFO] django.utils.autoreload: Watching for file changes with StatReloader
2025-10-30 00:55:06,555 [INFO] myapp.views: start order to register
2025-10-30 00:55:06,560 [ERROR] myapp.views: this email is already exist
2025-10-30 00:55:06,560 [ERROR] myapp.views: something happend this email is already exist
2025-10-30 00:55:06,567 [ERROR] myapp.exceptions: ValueError Caught: Error : this email is already exist in view register
2025-10-30 00:55:06,569 [WARNING] django.request: Bad Request: /api/hello/
2025-10-30 00:56:27,189 [INFO] django.utils.autoreload: C:\Users\DELL\Desktop\Posts\myproject\myapp\exceptions.py changed, reloading.
2025-10-30 00:56:28,547 [INFO] django.utils.autoreload: Watching for file changes with StatReloader
